Workbook

Sheet PA CAPA
B2: Programa de Ação 2026 com base no Plano Estratégico 2026
B5: Acordo entre Líder e Liderado
B6: Área: Postos, Região do Sisal | N6: Rota. Indicador RH
B7: Líder da Equipe | D7: Ingrid | N7: CLT | O7: EST | P7: R$
B8: Líder direto | D8: Viviane | N8: 14 | O8: 5 | P8: =230000/N8 -> 16428.571
B9: Substituto | D9: A definir | N9: 13 | O9: 4 | P9: =213000/N9 -> 16384.615
B10: Equipe | D10: Santa Luz: Liliane (coleta e atend) Quele Vitório (atend. e col.) Indiara(Coleta), Antony(Est. Coleta), Ítalo Henrique ( Estagiários atend. e col) Maria eduarda (atend e col) - estg vida ativa + suporte aos sabados de slc. UVL Valente: Irailma (coleta e atend), Ingredy ( estag. coleta e atend) COI Coité: Kailane (atende e col.), Alice (coleta e atend), Beatriz (estag. atende e coleta) Riachão do Jacuípe: Raiane (Atende e coleta)
B11: Foco | D11: Melhorar a infraestrutura, formar equipe e alcançar meta de faturamento
B12: Estratégias Delegadas e Resultados Pactuados
B13: Prioridade 1 | D13: Acompanhar indicadores de desempenho. | E13: Meta | F13: Peso | G13: Prazo Início | H13: Prazo Término | I13: Indicador | L13: Aferição
B14: Resultado 1.1 | D14: Alcançar Faturamento projetado | E14: 1 | F14: 0.06 | G14: 01.01 | H14: 31.12 | I14: % de alcance do fat. Projetado | L14: Cronograma Evolução Unidades
B15: Resultado 1.2 | D15: Indice de particular e convenios | E15: acomp | G15: 01.01 | H15: 31.12 | I15: acompanhar | L15: Cronograma Evolução Unidades
B16: Resultado 1.3 | D16: Indice de crescimento ao ano e com relação a meta | E16: 0.15 | G16: 01.01 | H16: 31.12 | I16: % de crescimento | L16: Cronograma Evolução Unidades
B17: Resultado 1.4 | D17: Pacientes, Exames, TK médio | E17: acomp | F17: 0.06 | G17: 01.01 | H17: 31.12 | I17: acompanhar | L17: Cronograma Evolução Unidades
B18: Resultado 1.5 | D18: Indice de exames por paciente | E18: % | G18: 01.01 | H18: 31.12 | I18: acompanhar | L18: Cronograma Evolução Unidades
B19: Resultado 1.6 | D19: Garantir o indice de novos pacientes | E19: ? | F19: 0.06 | G19: 01.01 | H19: 31.12 | I19: acompanhar | L19: Cronograma Evolução Unidades
B20: Resultado 1.7 | D20: Garantir o % NPS de satisfação do cliente por unidade | E20: 0.8 | F20: 0.06 | G20: 01.01 | H20: 31.12 | I20: % de satisfação | L20: Cronograma Evolução Unidades
B21: Resultado 1.8 | D21: Gerir e converter Orçamento registrado | E21: 0.75 | F21: 0.06 | G21: 01.01 | H21: 31.12 | I21: % de orçamentos convertidos | L21: Cronograma Evolução Unidades
B22: Resultado 1.9 | D22: Indice de pacientes perdidos | E22: ? | G22: 01.01 | H22: 31.12 | I22: acompanhar | L22: Cronograma Evolução Unidades
B23: Resultado 1.10 | D23: Indice de descontos | E23: % | G23: 01.01 | H23: 31.12 | I23: media por unidade | L23: Cronograma Evolução Unidades
B24: Resultado 1.11 | D24: indice de fluxo financeiro | E24: R$ | G24: 01.01 | H24: 31.12 | I24: R$ | L24: Cronograma Evolução Unidades
B25: Resultado 1.12 | D25: Indice de faturamento por colaborador | E25: 20k | F25: 0.06 | G25: 01.01 | H25: 31.12 | I25: acompanhar | L25: Cronograma Evolução Unidades
B26: Resultado 1.13 | D26: Ranking de medicos solicitantes | E26: acomp | F26: 0.06 | G26: 01.01 | H26: 31.12 | I26: acompanhar | L26: Cronograma Evolução Unidades
B27: Resultado 1.14 | D27: Medir produtividade (R$ e Qtd.) pacientes por recepcionista | E27: acomp | F27: 0.06 | G27: 01.01 | H27: 31.12 | I27: por unidade | L27: Cronograma Evolução Unidades
B28: Resultado 1.15 | D28: Acompanhar cortesias e cobertura | E28: acomp | G28: 01.01 | H28: 31.12 | I28: acompanhar | L28: Relatorio Smart
B29: Resultado 1.16 | D29: Acompanhar erro Internos de fechamento de caixa por recepcionistas | E29: 0 | F29: 0.06 | G29: 01.01 | H29: 31.12 | I29: % de erros | L29: Relatorio Smart
B30: Resultado 1.17 | D30: Reduzir indice de Guias em aberto, pendentes e canceladas | E30: 0 | F30: 0.06 | G30: 01.01 | H30: 31.12 | I30: acompanhar | L30: Relatorio Smart
B31: Resultado 1.18 | D31: Acompanhar Glosa Externa por recepcionista | E31: 0 | F31: 0.06 | G31: 01.01 | H31: 31.12 | I31: % de glosa externa | L31: Relatorio Smart
B32: Prioridade 2 | D32: Atrair, formar e reter talentos e equipes. | E32: Meta | F32: Peso | G32: Prazo Início | H32: Prazo Término | I32: Indicador | L32: Aferição
B33: Resultado 2.1 | D33: Realizar visitas mensais aos Postos de Coleta | E33: 1 | F33: 0.15 | G33: 01.01 | H33: 31.12 | I33: Qtd. de vezes por mês | L33: De segunda a sabado
B34: Resultado 2.2 | D34: Realizar as Reuniões de alinhamento com a equipe | E34: 4 | F34: 0.15 | G34: 01.01 | H34: 31.12 | I34: Reuniões trimestrais | L34: Ata das reuniões com a equipe.
B35: Resultado 2.3 | D35: Coordenar os Ciclos de treinamentos para as equipes dos postos. | E35: 12 | F35: 0.1 | G35: 01.01 | H35: 31.12 | I35: Qtd. Cursos Web e presenciais | L35: Registro.
B36: Resultado 2.4 | D36: Coordenar e aplicar as Avalições de Desempenho na rota | E36: 1 | G36: 01.01 | H36: 31.12 | I36: % dos liderados avaliados | L36: Avaliação de desempenho
B37: Prioridade 3 | E37: Meta | F37: Peso | G37: Prazo Início | H37: Prazo Término | I37: Indicador | L37: Aferição
B38: Resultado 3.1 | D38: Ações comerciais e de marketing | E38: 2 | G38: 01.01 | H38: 31.12
B39: Prioridade 4 | E39: Meta | F39: Peso | G39: Prazo Início | H39: Prazo Término | I39: Indicador | L39: Aferição
B40: Resultado 4.1 | D40: Identificar oportunidades de expanssão | E40: 2 | G40: 01.01 | H40: 31.12 | I40: Qud. De unidades abertas | L40: Unidades abertas
B41: Resultado 4.2 | D41: Reduzir custos com manutençoes de Ar condicionado, impressoras. | G41: 01.01 | H41: 31.12
B42: Resultado 4.3 | D42: Reforma das unidade (Pintura,piso, | G42: 01.01 | H42: 31.12
B43: Sistema de Comunicação e Informações
...

Sheet 1. SANTA LUZ
B2: PROJEÇÃO POSTOS SANTA LUZ CENTRO
B5: 2021 | C5: JAN | D5: FEV | E5: MAR | F5: ABR | G5: MAI | H5: JUN | I5: JUL | J5: AGO | K5: SET | L5: OUT | M5: NOV | N5: DEZ
B6: meta 2021 | D6: 10000 | E6: 10000 | F6: 10000 | G6: 10000 | H6: 10000 | I6: 15000 | J6: 15000 | K6: 15000 | L6: 20000 | M6: 20000 | N6: 20000 | O6: =SUM(D6:N6) -> 155000
E7: 13000 | F7: 13000 | G7: 13000 | H7: 18000 | I7: 22000 | J7: 22000 | K7: 22000
B8: Convênio | C8: 456.21 | D8: 5261.87 | E8: 4169.69 | F8: 5637.42 | G8: 4377.69 | H8: 4835.07 | I8: 8954.85 | J8: 5327.83 | K8: 4460.3 | L8: 10921.05 | M8: 11667.51 | N8: 10490.07
B9: Particular | C9: 2938.36 | D9: 7555.5 | E9: 9639.19 | F9: 12714.53 | G9: 18482.37 | H9: 20441.2 | I9: 14911.63 | J9: 16666.7 | K9: 18080.49 | L9: 26318.46 | M9: 28898.34 | N9: 18391.68
B10: REALIZADO 2021 | C10: =C8+C9 -> 3394.57 | D10: =D8+D9 -> 12817.37 | E10: =E8+E9 -> 13808.88 | F10: =F8+F9 -> 18351.95 | G10: =G8+G9 -> 22860.06 | H10: =H8+H9 -> 25276.27 | I10: =I8+I9 -> 23866.48 | J10: =J8+J9 -> 21994.53 | ... N10: =N8+N9 -> 28881.75 | O10: =SUM(C10:N10) -> 271598.01
B11: base meta 2019
B12: ano anterior
B14: 2021 | C14: JAN | D14: FEV | E14: MAR | F14: ABR | G14: MAI | H14: JUN | I14: JUL | J14: AGO | K14: SET | L14: OUT | M14: NOV | N14: DEZ
B15: Pacientes | C15: 95 | D15: 101 | E15: 159 | F15: 162 | G15: 210 | H15: 182 | I15: =24+191 -> 215 | J15: =206+23 -> 229 | K15: =214+21 -> 235 | L15: =28+308 -> 336 | M15: =39+352 -> 391 | N15: 239
B16: Exames | C16: 1144 | D16: 774 | E16: 716 | F16: 900 | G16: 1173 | H16: 1274 | I16: =466+772 -> 1238 | J16: =444+969 -> 1413 | K16: =1108+417 -> 1525 | L16: =1423+646 -> 2069 | M16: =819+1493 -> 2312 | N16: 1680
B17: tk medio | C17: =C10/C15 -> 35.732316 | D17: =D10/D15 -> 126.90465 | E17: =E10/E15 -> 86.848302 | F17: =F10/F15 -> 113.28364 | G17: =G10/G15 -> 108.85743 | H17: =H10/H15 -> 138.8806 | I17: =I10/I15 -> 111.00688 | J17: =J10/J15 -> 96.045983 | ... N17: =N10/N15 -> 120.84414
B18: indice de satisfação | C18: 0.55 | D18: 0.6 | E18: 0.92 | F18: 0.83 | G18: 1 | H18: 1 | I18: 0.88 | J18: 0.82 | K18: 1 | L18: 0.8 | M18: 0.8
B20: 2022 | C20: JAN | D20: FEV | E20: MAR | F20: ABR | G20: MAI | H20: JUN | I20: JUL | J20: AGO | K20: SET | L20: OUT | M20: NOV | N20: DEZ
B21: meta 2022 35 MIL | C21: 20000 | D21: 20000 | E21: 23000 | F21: 23000 | G21: 23000 | H21: 20000 | I21: 20000 | J21: 30000 | K21: 30000 | L21: 35000 | M21: 35000 | N21: 30000 | O21: =SUM(C21:N21) -> 309000
B22: Convênio | C22: 6462.6 | D22: 7597.49 | E22: 10494.36 | F22: 9231.46 | G22: 11726.49 | H22: 3790.34 | I22: 10179.37 | J22: 15486.76 | K22: 9481.07 | L22: 6130.34 | M22: 13930.43 | N22: 15610.88
B23: Particular | C23: 24383.38 | D23: 34389.26 | E23: 26482.19 | F23: 17365.22 | G23: 24438.74 | H23: 23299.33 | I23: 22895.77 | J23: 27008.03 | K23: 28273.58 | L23: 33579.39 | M23: 36442.58 | N23: 21782.12
B24: REALIZADO 2022 | C24: =C22+C23 -> 30845.98 | D24: =D22+D23 -> 41986.75 | E24: =E22+E23 -> 36976.55 | F24: =F22+F23 -> 26596.68 | G24: =G22+G23 -> 36165.23 | H24: =H22+H23 -> 27089.67 | I24: =I22+I23 -> 33075.14 | J24: =J22+J23 -> 42494.79 | ... N24: =N22+N23 -> 37393 | O24: =SUM(C24:N24) -> 440461.18 | P24: =O24/O10 -> 1.6217393
B25: base meta 2022 | C25: =(C24/C21)-1 -> 0.542299 | D25: =(D24/D21)-1 -> 1.0993375 | E25: =(E24/E21)-1 -> 0.60767609 | F25: =(F24/F21)-1 -> 0.15637739 | G25: =(G24/G21)-1 -> 0.5724013 | H25: =(H24/H21)-1 -> 0.3544835 | I25: =(I24/I21)-1 -> 0.653757 | J25: =(J24/J21)-1 -> 0.416493 | ... N25: =(N24/N21)-1 -> 0.24643333
B26: ano anterior | F26: =(F24/F10)-1 -> 0.44925635 | G26: =(G24/G10)-1 -> 0.58202691 | H26: =(H24/H10)-1 -> 0.07174318 | I26: =(I24/I10)-1 -> 0.38584073 | J26: =(J24/J10)-1 -> 0.93206174 | K26: =(K24/K10)-1 -> 0.67494795 | L26: =(L24/L10)-1 -> 0.066333311 | M26: =(M24/M10)-1 -> 0.24175902 | N26: =(N24/N10)-1 -> 0.29469302
B27: Orçamento Registrado
B28: Orçamento Registrado | C28: 10000 | M28: 69082.47 | N28: =N29+N30 -> 38435.11
B29: Orçamento Convertido | C29: 2000 | M29: 39814.8 | N29: 22641.79
B30: Orçamento NÃO Convertido | C30: 8000 | M30: 29267.67 | N30: 15793.32
B31: % de conversão | C31: =C29/C28 -> 0.2 | D31: =D29/D28 -> #DIV/0! | E31: =E29/E28 -> #DIV/0! | F31: =F29/F28 -> #DIV/0! | G31: =G29/G28 -> #DIV/0! | H31: =H29/H28 -> #DIV/0! | I31: =I29/I28 -> #DIV/0! | J31: =J29/J28 -> #DIV/0! | ... N31: =N29/N28 -> 0.58909133
B33: 2022 - indicadores | C33: JAN | D33: FEV | E33: MAR | F33: ABR | G33: MAI | H33: JUN | I33: JUL | J33: AGO | K33: SET | L33: OUT | M33: NOV | N33: DEZ
B34: pacientes novos | I34: 110 | J34: 127 | K34: 108 | L34: 188 | M34: 151 | N34: 33
B35: pacientes | C35: =247+28 -> 275 | D35: 365 | E35: =285+29 -> 314 | F35: =32+202 -> 234 | G35: =36+296 -> 332 | H35: =256+25 -> 281 | I35: =232+37 -> 269 | J35: =280+55 -> 335 | K35: =29+277 -> 306 | L35: =29+386 -> 415 | M35: 438 | N35: 264
B36: exames | C36: =565+1200 -> 1765 | D36: 2097 | E36: =627+2028 -> 2655 | F36: =632+1527 -> 2159 | G36: =822+1456 -> 2278 | H36: =1338+354 -> 1692 | I36: =806+1368 -> 2174 | J36: =1166+2098 -> 3264 | K36: =680+2117 -> 2797 | L36: =573+2079 -> 2652 | M36: 5810 | N36: 3343
B37: tk medio | C37: =C24/C35 -> 112.1672 | D37: =D24/D35 -> 115.03219 | E37: =E24/E35 -> 117.75971 | F37: =F24/F35 -> 113.66103 | G37: =G24/G35 -> 108.93142 | H37: =H24/H35 -> 96.40452 | I37: =I24/I35 -> 122.95591 | J37: =J24/J35 -> 126.85012 | ... N37: =N24/N35 -> 141.64015
B38: indice de satisfação | C38: 1 | D38: 0.6 | E38: 0.92 | F38: 0.83 | G38: 1 | H38: 1 | I38: 1 | J38: 0.89 | K38: 0.94 | L38: 0.88 | M38: 0.88 | N38: 0.84
B40: 2023 | C40: JAN | D40: FEV | E40: MAR | F40: ABR | G40: MAI | H40: JUN | I40: JUL | J40: AGO | K40: SET | L40: OUT | M40: NOV | N40: DEZ
B41: meta 2023 | C41: 30000 | D41: 35000 | E41: 45000 | F41: 45000 | G41: 45000 | H41: 35000 | I41: 35000 | J41: 45000 | K41: 45000 | L41: 45000 | M41: 45000 | N41: 35000 | O41: =SUM(C41:N41) -> 485000 | P41: =(O41/O24)-1 -> 0.1011186
F42: 60000 | G42: 60000 | I42: boas energias | J42: 60000 | K42: 60000 | L42: 60000 | M42: 60000
B43: Convênio | C43: 6888.43 | D43: 16436.94 | E43: 25990.42 | F43: 23921.62 | G43: 13888.13 | H43: 17693.11 | I43: 22985.03 | J43: 17944.2 | K43: 10197.57 | L43: 12501.25 | M43: 19766.93 | N43: 8736.11
B44: Particular | C44: 28157.08 | D44: 36782.36 | E44: 35874.93 | F44: 35593.15 | G44: 38234.51 | H44: 31066.55 | I44: 33136.94 | J44: 46859.31 | K44: 37421.79 | L44: 43675.5 | M44: 49301.23 | N44: 28672.47
B45: REALIZADO 2023 | C45: =C43+C44 -> 35045.51 | D45: =D43+D44 -> 53219.3 | E45: =E43+E44 -> 61865.35 | F45: =F43+F44 -> 59514.77 | G45: =G43+G44 -> 52122.64 | H45: =H43+H44 -> 48759.66 | I45: =I43+I44 -> 56121.97 | J45: =J43+J44 -> 64803.51 | K45: 47619.36 | L45: =L43+L44 -> 56176.75 | M45: 69068.16 | N45: =N43+N44 -> 37408.58 | O45: =SUM(C45:N45) -> 641725.56 | P45: =O45/O24 -> 1.4569401
B46: base meta 2022 | C46: =(C45/C41)-1 -> 0.16818367 | D46: =(D45/D41)-1 -> 0.52055143 | E46: =(E45/E41)-1 -> 0.37478556 | F46: =(F45/F41)-1 -> 0.32255044 | G46: =(G45/G41)-1 -> 0.15828089 | H46: =(H45/H41)-1 -> 0.39313314 | I46: =(I45/I41)-1 -> 0.60348486 | J46: =(J45/J41)-1 -> 0.440078 | ... N46: =(N45/N41)-1 -> 0.068816571
B47: ano anterior | C47: =(C45/C24)-1 -> 0.13614513 | D47: =(D45/D24)-1 -> 0.26752606 | E47: =(E45/E24)-1 -> 0.67309687 | F47: =(F45/F24)-1 -> 1.2376767 | G47: =(G45/G24)-1 -> 0.44123624 | H47: =(H45/H24)-1 -> 0.79993555 | I47: =(I45/I24)-1 -> 0.69680219 | J47: =(J45/J24)-1 -> 0.52497541 | ... N47: =(N45/N24)-1 -> 0.00041665552
...

Sheet 3. COITÉ 
B2: PROJEÇÃO POSTOS CONCEIÇÃO DO COITÉ
B5: 2020 | C5: JAN | D5: FEV | E5: MAR | F5: ABR | G5: MAI | H5: JUN | I5: JUL | J5: AGO | K5: SET | L5: OUT | M5: NOV | N5: DEZ
B6: meta 2020 | G6: 5000 | H6: 5000 | I6: 5000 | J6: 5000 | K6: 5000 | L6: 5000 | M6: 10000 | N6: 10000
B7: Nova meta corona virus | G7: 2500 | H7: =H6/2 -> 2500
B8: Convênio | G8: 113.15 | H8: 705.9 | I8: 1071.77 | J8: 2986.76 | K8: 3210.4 | L8: 2477.71 | M8: 713.93 | N8: 431.2
B9: Particular | G9: 210 | H9: 1411 | I9: 3948.82 | J9: 2050.8 | K9: 1952 | L9: 2677 | M9: 2704.5 | N9: 1523.25
B10: PROJEÇÃO 2020 | G10: =SUM(G8+G9) -> 323.15 | H10: =SUM(H8+H9) -> 2116.9 | I10: =SUM(I8+I9) -> 5020.59 | J10: =SUM(J8+J9) -> 5037.56 | K10: =SUM(K8+K9) -> 5162.4 | L10: =SUM(L8+L9) -> 5154.71 | M10: =SUM(M8+M9) -> 3418.43 | N10: 1954.45 | O10: =SUM(G10:N10) -> 28188.19 | P10: =O10/8 -> 3523.5237
B11: base meta 2020
B12: ano anterior
B14: 2021 | C14: JAN | D14: FEV | E14: MAR | F14: ABR | G14: MAI | H14: JUN | I14: JUL | J14: AGO | K14: SET | L14: OUT | M14: NOV | N14: DEZ
B15: meta 2021 | C15: 5000 | D15: 5000 | E15: 5000 | F15: 5000 | G15: 5000 | H15: 5000 | I15: 10000 | J15: 15000 | K15: 15000 | L15: 15000 | M15: 15000 | N15: 15000 | O15: =SUM(C15:N15) -> 115000
J16: 10000 | K16: 10000 | L16: 14000 | M16: 14000 | N16: 13000
B17: Convênio | C17: 1259.45 | D17: 3757.18 | E17: 2431.69 | F17: 1725.98 | G17: 1614.98 | H17: 1681.67 | I17: 3112.12 | J17: 6047.77 | K17: 9143.24 | L17: 5195.48 | M17: 6489.37 | N17: 6117.12
B18: Particular | C18: 1526.38 | D18: 1807.91 | E18: 3765.18 | F18: 4142.56 | G18: 3985 | H18: 5202.08 | I18: 3771 | J18: 4044 | K18: 4821 | L18: 4184.8 | M18: 2516.61 | N18: 3801
B19: REALIZADO 2021 | C19: =C17+C18 -> 2785.83 | D19: =D17+D18 -> 5565.09 | E19: =E17+E18 -> 6196.87 | F19: =F17+F18 -> 5868.54 | G19: =G17+G18 -> 5599.98 | H19: =H17+H18 -> 6883.75 | I19: =I17+I18 -> 6883.12 | J19: =J17+J18 -> 10091.77 | ... N19: =N17+N18 -> 9918.12 | O19: =SUM(C19:N19) -> 92143.57 | P19: =O19/10 -> 9214.357
B20: base meta 2020
B21: ano anterior
B23: 2020 | G23: MAI | H23: JUN | I23: JUL | J23: AGO | K23: SET | L23: OUT | M23: NOV | N23: DEZ
B24: Pacientes | G24: 4 | H24: 27 | I24: 48 | J24: 42 | K24: 33 | L24: 44
B25: Exames | G25: 12 | H25: 128 | I25: 288 | J25: 406 | K25: 353 | L25: 388
B26: tk medio | G26: =G24/G25 -> 0.33333333 | H26: =H24/H25 -> 0.2109375 | I26: =I24/I25 -> 0.16666667 | J26: =J24/J25 -> 0.10344828 | K26: =K24/K25 -> 0.093484419 | L26: =L24/L25 -> 0.11340206 | M26: =#REF!/M24 -> #REF! | N26: =#REF!/N24 -> #REF!
B28: 2021 | C28: JAN | D28: FEV | E28: MAR | F28: ABR | G28: MAI | H28: JUN | I28: JUL | J28: AGO | K28: SET | L28: OUT | M28: NOV | N28: DEZ
B29: pacientes | C29: 26 | D29: 31 | E29: 31 | F29: 46 | G29: 49 | H29: 58 | I29: =14+33 -> 47 | J29: =22+41 -> 63 | K29: =30+30 -> 60 | L29: =23+37 -> 60 | M29: =37+18 -> 55 | N29: 47
B30: exames | C30: 227 | D30: 415 | E30: 320 | F30: 377 | G30: 406 | H30: 476 | I30: =323+163 -> 486 | J30: =608+262 -> 870 | K30: =263+886 -> 1149 | L30: =224+461 -> 685 | M30: =138+564 -> 702 | N30: 832
B31: tk medio | C31: =C19/C29 -> 107.14731 | D31: =D19/D29 -> 179.51903 | E31: =E19/E29 -> 199.89903 | F31: =F19/F29 -> 127.57696 | G31: =G19/G29 -> 114.28531 | H31: =H19/H29 -> 118.68534 | I31: =I19/I29 -> 146.44936 | J31: =J19/J29 -> 160.18683 | ... N31: =N19/N29 -> 211.02383
B32: indice de satisfação | C32: 0.5 | D32: 0.66 | E32: 1 | F32: 0 | G32: 1 | H32: 1 | I32: 1 | J32: 1 | K32: 1 | L32: 0.83 | M32: 1
B34: 2022 | C34: JAN | D34: FEV | E34: MAR | F34: ABR | G34: MAI | H34: JUN | I34: JUL | J34: AGO | K34: SET | L34: OUT | M34: NOV | N34: DEZ
B35: meta 2022 | C35: 13000 | D35: 13000 | E35: 15000 | F35: 15000 | G35: 15000 | H35: 13000 | I35: 13000 | J35: 15000 | K35: 15000 | L35: 15000 | M35: 15000 | N35: 13000 | O35: =SUM(C35:N35) -> 170000
B36: Convênio | C36: 6293.87 | D36: 5397.23 | E36: 18224.06 | F36: 25305.65 | G36: 9558.5 | H36: 10126.11 | I36: 8836.06 | J36: 13533.77 | K36: 12468.35 | L36: 9836.46 | M36: 5043.31 | N36: 4695.23
B37: Particular | C37: 2275 | D37: 1857 | E37: 2412 | F37: 3192 | G37: 3230 | H37: 3705.46 | I37: 2114 | J37: 2018 | K37: 2630 | L37: 2080 | M37: 3380 | N37: 1960
B38: REALIZADO 2022 | C38: =C36+C37 -> 8568.87 | D38: =D36+D37 -> 7254.23 | E38: =E36+E37 -> 20636.06 | F38: =F36+F37 -> 28497.65 | G38: =G36+G37 -> 12788.5 | H38: =H36+H37 -> 13831.57 | I38: =I36+I37 -> 10950.06 | J38: =J36+J37 -> 15551.77 | ... N38: =N36+N37 -> 6655.23 | O38: =SUM(C38:N38) -> 160172.06 | P38: =O38+O19+O10 -> 280503.82
B39: CÁLCULO VARIÁVEL | C39: =(C38-C35)*0.01 -> -44.3113 | D39: =(D38-D35)*0.01 -> -57.4577 | E39: =(E38-E35)*0.01 -> 56.3606 | F39: =(F38-F35)*0.01 -> 134.9765 | G39: =(G38-G35)*0.01 -> -22.115 | H39: =(H38-H35)*0.01 -> 8.3157 | I39: =(I38-I35)*0.01 -> -20.4994 | J39: =(J38-J35)*0.01 -> 5.5177 | ... N39: =(N38-N35)*0.01 -> -63.4477
B40: base meta 2021
B41: ano anterior
B42: Orçamento Registrado
B43: Orçamento Registrado | C43: 10000 | M43: 6816.27
B44: Orçamento Convertido | C44: 2000 | M44: 3607.43
B45: Orçamento NÃO Convertido | C45: 8000 | M45: 3208.84
B46: % de conversão | C46: =C44/C43 -> 0.2 | D46: =D44/D43 -> #DIV/0! | E46: =E44/E43 -> #DIV/0! | F46: =F44/F43 -> #DIV/0! | G46: =G44/G43 -> #DIV/0! | H46: =H44/H43 -> #DIV/0! | I46: =I44/I43 -> #DIV/0! | J46: =J44/J43 -> #DIV/0! | ... N46: =N44/N43 -> #DIV/0!
B48: 2022 - indicadores | C48: JAN | D48: FEV | E48: MAR | F48: ABR | G48: MAI | H48: JUN | I48: JUL | J48: AGO | K48: SET | L48: OUT | M48: NOV | N48: DEZ
...

Sheet 4. VALENTE 
B1: PROJEÇÃO POSTOS VALENTE
B4: 2021 | C4: JAN | D4: FEV | E4: MAR | F4: ABR | G4: MAI | H4: JUN | I4: JUL | J4: AGO | K4: SET | L4: OUT | M4: NOV | N4: DEZ
B5: meta 2021 | M5: 5000 | N5: 5000
B6: Convênio | M6: 1562.81 | N6: 823.37
B7: Particular | M7: 3895.4 | N7: 3174
B8: REALIZADO 2021 | M8: =M6+M7 -> 5458.21 | N8: =N7+N6 -> 3997.37
B9: base meta
B11: 2021 | C11: JAN | D11: FEV | E11: MAR | F11: ABR | G11: MAI | H11: JUN | I11: JUL | J11: AGO | K11: SET | L11: OUT | M11: NOV | N11: DEZ
B12: pacientes | M12: =7+47 -> 54 | N12: 31
B13: exames | M13: =448+132 -> 580 | N13: 218
B14: tk medio | C14: =C8/C12 -> #DIV/0! | D14: =D8/D12 -> #DIV/0! | E14: =E8/E12 -> #DIV/0! | F14: =F8/F12 -> #DIV/0! | G14: =G8/G12 -> #DIV/0! | H14: =H8/H12 -> #DIV/0! | I14: =I8/I12 -> #DIV/0! | J14: =J8/J12 -> #DIV/0! | ... N14: =N8/N12 -> 128.94742
B15: indice de satisfação | L15: alimentar | M15: 0.8 | N15: alimentar
B18: 2022 | C18: JAN | D18: FEV | E18: MAR | F18: ABR | G18: MAI | H18: JUN | I18: JUL | J18: AGO | K18: SET | L18: OUT | M18: NOV | N18: DEZ
B19: meta 2022 | D19: 5000 | E19: 5000 | F19: 5000 | G19: 5000 | H19: 5000 | I19: 5000 | J19: 10000 | K19: 10000 | L19: 10000 | M19: 10000 | N19: 10000 | O19: =SUM(C19:N19) -> 80000
B20: Convênio | C20: 1555.71 | D20: 2908.27 | E20: 1526.85 | F20: 3834.66 | G20: 2247.78 | H20: 2418.97 | I20: 2641.18 | J20: 2386.03 | K20: 5877.92 | L20: 5034.3 | M20: 6293 | N20: 2980.1
B21: Particular | C21: 3563.6 | D21: 3235.2 | E21: 3664.2 | F21: 3330.2 | G21: 4629.88 | H21: 4507.2 | I21: 3807.7 | J21: 7884.42 | K21: 4748 | L21: 5556 | M21: 5414 | N21: 3950
B22: REALIZADO 2022 | C22: =C20+C21 -> 5119.31 | D22: =D20+D21 -> 6143.47 | E22: =E20+E21 -> 5191.05 | F22: =F20+F21 -> 7164.86 | G22: =G20+G21 -> 6877.66 | H22: =H20+H21 -> 6926.17 | I22: =I20+I21 -> 6448.88 | J22: =J20+J21 -> 10270.45 | ... N22: =N20+N21 -> 6930.1 | O22: =SUM(C22:N22) -> 93995.17
B23: base meta 2021
B24: ano anterior
B26: Orçamento Registrado
B27: Orçamento Registrado | C27: 10000 | M27: 14393.28 | N27: =N28+N29 -> 8296.35
B28: Orçamento Convertido | C28: 2000 | M28: 7652.82 | N28: 4604.12
B29: Orçamento NÃO Convertido | C29: 8000 | M29: 6740.46 | N29: 3692.23
B30: % de conversão | C30: =C28/C27 -> 0.2 | D30: =D28/D27 -> #DIV/0! | E30: =E28/E27 -> #DIV/0! | F30: =F28/F27 -> #DIV/0! | G30: =G28/G27 -> #DIV/0! | H30: =H28/H27 -> #DIV/0! | I30: =I28/I27 -> #DIV/0! | J30: =J28/J27 -> #DIV/0! | ... N30: =N28/N27 -> 0.5549573
B32: 2022 - indicadores | C32: JAN | D32: FEV | E32: MAR | F32: ABR | G32: MAI | H32: JUN | I32: JUL | J32: AGO | K32: SET | L32: OUT | M32: NOV | N32: DEZ
B33: pacientes novos | I33: 26 | J33: 34 | K33: 29 | L33: 39 | M33: 42 | N33: 33
B34: pacientes | C34: =7+35 -> 42 | D34: 47 | E34: =6+50 -> 56 | F34: =7+35 -> 42 | G34: =59+8 -> 67 | H34: =61+8 -> 69 | I34: =52+12 -> 64 | J34: =67+12 -> 79 | K34: =12+54 -> 66 | L34: =63+10 -> 73 | M34: 83 | N34: 58
B35: exames | C35: =154+120 -> 274 | D35: 260 | E35: =194+231 -> 425 | F35: =175+312 -> 487 | G35: =186+139 -> 325 | H35: =246+224 -> 470 | I35: =139+182 -> 321 | J35: =127+386 -> 513 | K35: =293+294 -> 587 | L35: =327+368 -> 695 | M35: 951 | N35: 513
B36: tk medio | C36: =C22/C34 -> 121.88833 | D36: =D22/D34 -> 130.71213 | E36: =E22/E34 -> 92.697321 | F36: =F22/F34 -> 170.5919 | G36: =G22/G34 -> 102.65164 | H36: =H22/H34 -> 100.37928 | I36: =I22/I34 -> 100.76375 | J36: =J22/J34 -> 130.0057 | ... N36: =N22/N34 -> 119.48448
B37: indice de satisfação | C37: 1 | D37: 0.66 | E37: 1 | F37: 1 | G37: 1 | H37: 1 | I37: 1 | J37: 1 | K37: 1 | L37: 1 | M37: 1 | N37: 1
B39: 2023 | C39: JAN | D39: FEV | E39: MAR | F39: ABR | G39: MAI | H39: JUN | I39: JUL | J39: AGO | K39: SET | L39: OUT | M39: NOV | N39: DEZ
B40: meta 2023 | C40: 10000 | D40: 10000 | E40: 15000 | F40: 15000 | G40: 15000 | H40: 10000 | I40: 10000 | J40: 15000 | K40: 15000 | L40: 15000 | M40: 15000 | N40: 10000 | O40: =SUM(C40:N40) -> 155000
B41: Convênio | C41: 4679.69 | D41: 2573.65 | E41: 4183.02 | F41: 9132.82 | G41: 14388.32 | H41: 4518.96 | I41: 4538.41 | J41: 2477 | K41: 4624.04 | L41: 13390.52 | M41: 6877.71 | N41: 1627.17
B42: Particular | C42: 5371 | D42: 3906 | E42: 6987 | F42: 3606 | G42: 6903 | H42: 5378 | I42: 4240.02 | J42: 4157.4 | K42: 5911 | L42: 5123 | M42: 8138 | N42: 12385
B43: REALIZADO 2023 | C43: =C41+C42 -> 10050.69 | D43: =D41+D42 -> 6479.65 | E43: =E41+E42 -> 11170.02 | F43: =F41+F42 -> 12738.82 | G43: =G41+G42 -> 21291.32 | H43: =H41+H42 -> 9896.96 | I43: 8778.43 | J43: 6634.4 | K43: =K41+K42 -> 10535.04 | L43: =L41+L42 -> 18513.52 | M43: 15015.71 | N43: =N41+N42 -> 14012.17 | O43: =SUM(C43:N43) -> 145116.73
B44: base meta 2022
B45: ano anterior | C45: =(C43/C22)-1 -> 0.96328997 | D45: =(D43/D22)-1 -> 0.054721517 | E45: =(E43/E22)-1 -> 1.1517843 | F45: =(F43/F22)-1 -> 0.77795798 | G45: =(G43/G22)-1 -> 2.0957215 | H45: =(H43/H22)-1 -> 0.42892248 | I45: =(I43/I22)-1 -> 0.36123327 | J45: =(J43/J22)-1 -> -0.35403025 | ... M45: =(M43/M22)-1 -> 0.28262663
B47: Orçamento Registrado
B48: Orçamento Registrado | C48: =C49+C50 -> 12067.48 | D48: =D49+D50 -> 7500.34 | E48: =E49+E50 -> 14576.68 | F48: =F49+F50 -> 7411.36 | G48: =G49+G50 -> 12849.76 | H48: =H49+H50 -> 10136.7 | I48: =I49+I50 -> 6135.85 | J48: =J49+J50 -> 8463.91 | ... N48: =N49+N50 -> 18523.04
B49: Orçamento Convertido | C49: 6246.6 | D49: 5157.64 | E49: 8728.06 | F49: 4720.46 | G49: 8623.77 | H49: 6184.86 | I49: 4232.02 | J49: 5273.48 | K49: 6638.16 | L49: 7150.06 | M49: 8769.52 | N49: 15660.35
...

Sheet 2. RIAÇHÃO
B2: 2025 | C2: JAN | D2: FEV | E2: MAR | F2: ABR | G2: MAI | H2: JUN | I2: JUL | J2: AGO | K2: SET | L2: OUT | M2: NOV | N2: DEZ
B3: meta 2025 | J3: 12000 | K3: 12000 | L3: 12000 | M3: 12000 | N3: 12000 | O3: =SUM(C3:N3) -> 60000
B4: Convênio | K4: 189 | M4: 7185.99
B5: Particular | K5: 6881.3 | M5: 5095
B6: REALIZADO 2025 | G6: 6697.07 | H6: 7729.92 | I6: =2584.33+7750 -> 10334.33 | J6: 7206 | K6: 7050 | L6: 7317 | M6: 12292 | O6: =SUM(C6:N6) -> 58626.32

Sheet CONSOLIDADO
B2: 2025 | C2: JAN | D2: FEV | E2: MAR | F2: ABR | G2: MAI | H2: JUN | I2: JUL | J2: AGO | K2: SET | L2: OUT | M2: NOV | N2: DEZ
B3: meta 2025 | C3: ='1. SANTA LUZ'!C162+'2. RIAÇHÃO'!C3+'3. COITÉ '!C156+'4. VALENTE '!C138 -> 110551 | D3: ='1. SANTA LUZ'!D162+'2. RIAÇHÃO'!D3+'3. COITÉ '!D156+'4. VALENTE '!D138 -> 114972.45 | E3: ='1. SANTA LUZ'!E162+'2. RIAÇHÃO'!E3+'3. COITÉ '!E156+'4. VALENTE '!E138 -> 113267.09 | F3: ='1. SANTA LUZ'!F162+'2. RIAÇHÃO'!F3+'3. COITÉ '!F156+'4. VALENTE '!F138 -> 130415.71 | G3: ='1. SANTA LUZ'!G162+'2. RIAÇHÃO'!G3+'3. COITÉ '!G156+'4. VALENTE '!G138 -> 141228.59 | H3: ='1. SANTA LUZ'!H162+'2. RIAÇHÃO'!H3+'3. COITÉ '!H156+'4. VALENTE '!H138 -> 120000.18 | I3: ='1. SANTA LUZ'!I162+'2. RIAÇHÃO'!I3+'3. COITÉ '!I156+'4. VALENTE '!I138 -> 128841.11 | J3: ='1. SANTA LUZ'!J162+'2. RIAÇHÃO'!J3+'3. COITÉ '!J156+'4. VALENTE '!J138 -> 150641.62 | ... N3: ='1. SANTA LUZ'!N162+'2. RIAÇHÃO'!N3+'3. COITÉ '!N156+'4. VALENTE '!N138 -> 119299.64 | O3: =SUM(C3:N3) -> 1586983.6
B4: Convênio | C4: ='1. SANTA LUZ'!C163+'2. RIAÇHÃO'!C4+'3. COITÉ '!C157+'4. VALENTE '!C139 -> 51873.05 | D4: ='1. SANTA LUZ'!D163+'2. RIAÇHÃO'!D4+'3. COITÉ '!D157+'4. VALENTE '!D139 -> 48786.8 | E4: ='1. SANTA LUZ'!E163+'2. RIAÇHÃO'!E4+'3. COITÉ '!E157+'4. VALENTE '!E139 -> 56800.98 | F4: ='1. SANTA LUZ'!F163+'2. RIAÇHÃO'!F4+'3. COITÉ '!F157+'4. VALENTE '!F139 -> 53718.63 | G4: ='1. SANTA LUZ'!G163+'2. RIAÇHÃO'!G4+'3. COITÉ '!G157+'4. VALENTE '!G139 -> 44404.22 | H4: ='1. SANTA LUZ'!H163+'2. RIAÇHÃO'!H4+'3. COITÉ '!H157+'4. VALENTE '!H139 -> 33499.58 | I4: ='1. SANTA LUZ'!I163+'2. RIAÇHÃO'!I4+'3. COITÉ '!I157+'4. VALENTE '!I139 -> 68230.16 | J4: ='1. SANTA LUZ'!J163+'2. RIAÇHÃO'!J4+'3. COITÉ '!J157+'4. VALENTE '!J139 -> 54263.96 | ... N4: ='1. SANTA LUZ'!N163+'2. RIAÇHÃO'!N4+'3. COITÉ '!N157+'4. VALENTE '!N139 -> 17602.28 | O4: =SUM(C4:N4) -> 613595.27 | U4: =#REF!*1.15 -> #REF!
B5: Particular | C5: ='1. SANTA LUZ'!C164+'2. RIAÇHÃO'!C5+'3. COITÉ '!C158+'4. VALENTE '!C140 -> 72292.62 | D5: ='1. SANTA LUZ'!D164+'2. RIAÇHÃO'!D5+'3. COITÉ '!D158+'4. VALENTE '!D140 -> 61022.05 | E5: ='1. SANTA LUZ'!E164+'2. RIAÇHÃO'!E5+'3. COITÉ '!E158+'4. VALENTE '!E140 -> 73966.85 | F5: ='1. SANTA LUZ'!F164+'2. RIAÇHÃO'!F5+'3. COITÉ '!F158+'4. VALENTE '!F140 -> 72940.19 | G5: ='1. SANTA LUZ'!G164+'2. RIAÇHÃO'!G5+'3. COITÉ '!G158+'4. VALENTE '!G140 -> 87288.02 | H5: ='1. SANTA LUZ'!H164+'2. RIAÇHÃO'!H5+'3. COITÉ '!H158+'4. VALENTE '!H140 -> 68164.38 | I5: ='1. SANTA LUZ'!I164+'2. RIAÇHÃO'!I5+'3. COITÉ '!I158+'4. VALENTE '!I140 -> 81469.18 | J5: ='1. SANTA LUZ'!J164+'2. RIAÇHÃO'!J5+'3. COITÉ '!J158+'4. VALENTE '!J140 -> 106957.63 | ... N5: ='1. SANTA LUZ'!N164+'2. RIAÇHÃO'!N5+'3. COITÉ '!N158+'4. VALENTE '!N140 -> 46175.38 | O5: =SUM(C5:N5) -> 1014892.1
B6: realizado 2025 | C6: ='1. SANTA LUZ'!C165+'2. RIAÇHÃO'!C6+'3. COITÉ '!C159+'4. VALENTE '!C141 -> 124165.67 | D6: ='1. SANTA LUZ'!D165+'2. RIAÇHÃO'!D6+'3. COITÉ '!D159+'4. VALENTE '!D141 -> 109808.85 | E6: ='1. SANTA LUZ'!E165+'2. RIAÇHÃO'!E6+'3. COITÉ '!E159+'4. VALENTE '!E141 -> 130767.83 | F6: ='1. SANTA LUZ'!F165+'2. RIAÇHÃO'!F6+'3. COITÉ '!F159+'4. VALENTE '!F141 -> 126658.82 | G6: ='1. SANTA LUZ'!G165+'2. RIAÇHÃO'!G6+'3. COITÉ '!G159+'4. VALENTE '!G141 -> 138389.31 | H6: ='1. SANTA LUZ'!H165+'2. RIAÇHÃO'!H6+'3. COITÉ '!H159+'4. VALENTE '!H141 -> 109393.88 | I6: ='1. SANTA LUZ'!I165+'2. RIAÇHÃO'!I6+'3. COITÉ '!I159+'4. VALENTE '!I141 -> 160033.67 | J6: ='1. SANTA LUZ'!J165+'2. RIAÇHÃO'!J6+'3. COITÉ '!J159+'4. VALENTE '!J141 -> 168427.59 | ... M6: ='1. SANTA LUZ'!M165+'2. RIAÇHÃO'!M6+'3. COITÉ '!M159+'4. VALENTE '!M141 -> 171787.24 | N6: 118998 | O6: =SUM(C6:N6) -> 1722982.8
B7: cresc a.a | O7: =(O6/#REF!)-1 -> #REF!
B8: % | C8: =(C6/C3)-1 -> 0.12315288 | D8: =(D6/D3)-1 -> -0.044911608 | E8: =(E6/E3)-1 -> 0.15450861 | F8: =(F6/F3)-1 -> -0.028807002 | G8: =(G6/G3)-1 -> -0.020104162 | H8: =(H6/H3)-1 -> -0.088385689 | I8: =(I6/I3)-1 -> 0.24210095 | J8: =(J6/J3)-1 -> 0.11806809 | ... N8: =(N6/N3)-1 -> -0.0025283899 | O8: =O6/O3 -> 1.0856966
B10: BONUS | C10: =(3300)+(2000*C8) -> 3546.3058 | D10: 3000 | E10: =(3300)+(2000*E8) -> 3609.0172 | F10: 3000 | G10: 3000 | H10: 2500 | I10: =(3300)+(2000*I8) -> 3784.2019 | J10: =(3300)+(2000*J8) -> 3536.1362 | K10: =(3300)+(2000*K8) -> 3858.3587 | L10: =(3300)+(2000*L8) -> 3709.3588 | M10: =(3300)+(2000*M8) -> 3404.8458 | N10: 3000 | O10: =SUM(C10:N10) -> 39948.224 | P10: TOTAL ANO/ LIDERANÇA
O11: =SUM('1. SANTA LUZ'!M211+'3. COITÉ '!M204+'4. VALENTE '!M184) -> 3215.8897 | P11: TOTAL BALCÃO
B12: 2026 | C12: JAN | D12: FEV | E12: MAR | F12: ABR | G12: MAI | H12: JUN | I12: JUL | J12: AGO | K12: SET | L12: OUT | M12: NOV | N12: DEZ
B13: meta 2026 | C13: ='1. SANTA LUZ'!C339+'3. COITÉ '!C285+'4. VALENTE '!C265 -> 152000 | D13: ='1. SANTA LUZ'!D339+'3. COITÉ '!D285+'4. VALENTE '!D265 -> 145000 | E13: ='1. SANTA LUZ'!E339+'3. COITÉ '!E285+'4. VALENTE '!E265 -> 160000 | F13: ='1. SANTA LUZ'!F339+'3. COITÉ '!F285+'4. VALENTE '!F265 -> 155000 | G13: ='1. SANTA LUZ'!G339+'3. COITÉ '!G285+'4. VALENTE '!G265 -> 171059.34 | H13: ='1. SANTA LUZ'!H339+'3. COITÉ '!H285+'4. VALENTE '!H265 -> 134000 | I13: ='1. SANTA LUZ'!I339+'3. COITÉ '!I285+'4. VALENTE '!I265 -> 180412.21 | J13: ='1. SANTA LUZ'!J339+'3. COITÉ '!J285+'4. VALENTE '!J265 -> 189744.24 | ... N13: ='1. SANTA LUZ'!N339+'3. COITÉ '!N285+'4. VALENTE '!N265 -> 120693.93 | O13: =SUM(C13:N13) -> 2012468.7
B14: Particular | C14: 84442.38 | D14: ='1. SANTA LUZ'!D342+'3. COITÉ '!D288+'4. VALENTE '!D268 -> 0 | E14: ='1. SANTA LUZ'!E342+'3. COITÉ '!E288+'4. VALENTE '!E268 -> 0 | F14: ='1. SANTA LUZ'!F342+'3. COITÉ '!F288+'4. VALENTE '!F268 -> 0 | G14: ='1. SANTA LUZ'!G342+'3. COITÉ '!G288+'4. VALENTE '!G268 -> 0 | H14: ='1. SANTA LUZ'!H342+'3. COITÉ '!H288+'4. VALENTE '!H268 -> 0 | I14: ='1. SANTA LUZ'!I342+'3. COITÉ '!I288+'4. VALENTE '!I268 -> 0 | J14: ='1. SANTA LUZ'!J342+'3. COITÉ '!J288+'4. VALENTE '!J268 -> 0 | K14: ='1. SANTA LUZ'!K342+'3. COITÉ '!K288+'4. VALENTE '!K268 -> 0 | ... N14: ='1. SANTA LUZ'!N342+'3. COITÉ '!N288+'4. VALENTE '!N268 -> 0 | O14: =SUM(C14:N14) -> 84442.38
B15: Convênio | C15: 62547.39 | D15: ='1. SANTA LUZ'!D344+'3. COITÉ '!D287+'4. VALENTE '!D267 -> 0 | E15: ='1. SANTA LUZ'!E344+'3. COITÉ '!E287+'4. VALENTE '!E267 -> 0 | F15: ='1. SANTA LUZ'!F344+'3. COITÉ '!F287+'4. VALENTE '!F267 -> 0 | G15: ='1. SANTA LUZ'!G344+'3. COITÉ '!G287+'4. VALENTE '!G267 -> 0 | H15: ='1. SANTA LUZ'!H344+'3. COITÉ '!H287+'4. VALENTE '!H267 -> 0 | I15: ='1. SANTA LUZ'!I344+'3. COITÉ '!I287+'4. VALENTE '!I267 -> 0 | J15: ='1. SANTA LUZ'!J344+'3. COITÉ '!J287+'4. VALENTE '!J267 -> 0 | K15: ='1. SANTA LUZ'!K344+'3. COITÉ '!K287+'4. VALENTE '!K267 -> 0 | ... N15: ='1. SANTA LUZ'!N344+'3. COITÉ '!N287+'4. VALENTE '!N267 -> 0 | O15: =SUM(C15:N15) -> 62547.39 | U15: =#REF!*1.15 -> #REF!
B16: realizado 2026 | C16: ='1. SANTA LUZ'!C351+'3. COITÉ '!C289+'4. VALENTE '!C269 -> 146989.77 | D16: ='1. SANTA LUZ'!D341+'3. COITÉ '!D289+'4. VALENTE '!D269+'2. RIAÇHÃO'!D6 -> 0 | E16: ='1. SANTA LUZ'!E341+'3. COITÉ '!E289+'4. VALENTE '!E269+'2. RIAÇHÃO'!E6 -> 0 | F16: ='1. SANTA LUZ'!F341+'3. COITÉ '!F289+'4. VALENTE '!F269+'2. RIAÇHÃO'!F6 -> 0 | N16: ='1. SANTA LUZ'!N341+'3. COITÉ '!N289+'4. VALENTE '!N269+'2. RIAÇHÃO'!N6 -> 0
B17: cresc a.a | C17: =(C16/C6)-1 -> 0.18381973
B18: meta% | C18: =(C16/C13)-1 -> -0.032962039

Sheet Planilha2
